Workbook

Sheet Resumo
C1: PLANILHA RESUMO
C4: RELATÓRIO
C8: RESUMO
C9: Provisionamento Total | D9: =D47 -> -12317233
C10: Realizado | D10: =F47 -> -6634232.3
C11: Diferença Realizado x Provisionado | D11: =D10/D9 -> 0.53861387
E12: 1
D15: =1-D11 -> 0.46138613
C18: RESULTADO ANO
C21: Unidades | D21: Valor Provisionado | F21: Realizado | H21: Realizado x Provisionado
C22: =HSI!$C$3 -> HOSPITAL SANTA IZABEL | D22: =HSI!U12 -> -7049076.6 | F22: =HSI!U24 -> -4220507.5 | H22: =F22/D22 -> 0.59873196
C23: =Pupileira!$C$3 -> PUPILEIRA | D23: =Pupileira!$U$12 -> -464175.27 | F23: =Pupileira!$U$20 -> -241159.09 | H23: =F23/D23 -> 0.51954316
C24: ='Anexo HSI'!C3 -> ANEXO HSI | D24: ='Anexo HSI'!U12 -> -326689.11 | F24: ='Anexo HSI'!U20 -> -164649.69 | H24: =F24/D24 -> 0.50399504
C25: =HMS!C3 -> HOSPITAL MUNICIPAL DE SALVADOR | D25: =HMS!U12 -> -2886806.6 | F25: =HMS!U21 -> -1520780.4 | H25: =F25/D25 -> 0.5268037
C26: ='Curativos Especiais'!C3 -> Curativos Especiais | D26: ='Curativos Especiais'!U9 -> -116999.3 | F26: ='Curativos Especiais'!U16 -> -94814.49 | H26: =F26/D26 -> 0.81038508
C27: ='Casa de Apoio Solange Fraga'!C3 -> Casa de Apoio Solange Fraga | D27: ='Casa de Apoio Solange Fraga'!U10 -> -36746.081 | F27: ='Casa de Apoio Solange Fraga'!U18 -> -15339.98 | H27: =F27/D27 -> 0.41745894
C28: ='Infanto Juvenil'!C3 -> Unidade de Acolhimento Infanto Juvenil | D28: ='Infanto Juvenil'!U9 -> -8002.3594 | F28: ='Infanto Juvenil'!U16 -> -4955.84 | H28: =F28/D28 -> 0.61929735
C29: ='Casa Lad.7'!C3 -> Casa da Ladeira, 7 (Galpão de Obras) | D29: ='Casa Lad.7'!U9 -> -7177.7062 | F29: ='Casa Lad.7'!U16 -> -2888.1 | H29: =F29/D29 -> 0.40237088
C30: ='Clínica Rio Vermelho'!C3 -> Clínica Rio Vermelho | D30: ='Clínica Rio Vermelho'!U12 -> -68412.926 | F30: ='Clínica Rio Vermelho'!U21 -> -29352.958 | H30: =F30/D30 -> 0.42905573
C31: ='Clínica Ondina'!C3 -> Clínica Ondina | D31: ='Clínica Ondina'!U12 -> -71324.535 | F31: ='Clínica Ondina'!U21 -> -32498.109 | H31: =F31/D31 -> 0.45563716
C32: ='CCS 01'!C3 -> Cemitério Campo Santo, Entrada 1 | D32: ='CCS 01'!U12 -> -143334.29 | F32: ='CCS 01'!U21 -> -36940.884 | H32: =F32/D32 -> 0.25772537
C33: ='CCS 02'!C3 -> Cemitério Campo Santo, Entrada 2 | D33: ='CCS 02'!U13 -> -4899.475 | F33: ='CCS 02'!U22 -> 0 | H33: =F33/D33 -> 0
C34: ='Museu da Misericórdia'!C3 -> Museu da Misericórdia | D34: ='Museu da Misericórdia'!U12 -> -166549.69 | F34: ='Museu da Misericórdia'!U21 -> -96029.215 | H34: =F34/D34 -> 0.57657998
C35: ='Cuidado Continuo'!C3 -> Cuidado Contínuo | D35: ='Cuidado Continuo'!U13 -> -144016.75 | F35: ='Cuidado Continuo'!U22 -> -1180.53 | H35: =F35/D35 -> 0.0081971713
C36: ='Posto de Coleta'!C3 -> Posto de Coleta | D36: ='Posto de Coleta'!U13 -> -72862.591 | F36: ='Posto de Coleta'!U22 -> -9079.98 | H36: =F36/D36 -> 0.12461786
C37: =CAF!C3 -> CAF | D37: =CAF!U12 -> -372050.64 | F37: =CAF!U21 -> -83763.979 | H37: =F37/D37 -> 0.22514134
C38: =CAL!C3 -> Clínica Álvaro Lemos | D38: ='Casa Azul'!U12 -> -129892.08 | F38: =CAL!U21 -> -20352.145 | H38: =F38/D38 -> 0.15668503
C39: ='Casa Azul'!C3 -> Casa Azul | D39: ='CEI C.R'!U12 -> -8891.6242 | F39: ='Casa Azul'!U21 -> -21075.132 | H39: =F39/D39 -> 2.370223
C40: ='CEI C.R'!C3 -> CEI Cristo Redentor | D40: ='CEI C.R'!U12 -> -8891.6242 | F40: ='CEI C.R'!U21 -> -1230.001 | H40: =F40/D40 -> 0.13833254
C41: ='CER II'!C3 -> CER II | D41: ='CER II'!U12 -> -45687.273 | F41: ='CER II'!U21 -> -20814.095 | H41: =F41/D41 -> 0.45557752
C42: ='CEI S.A'!C3 -> CEI Santo Antônio | D42: ='CEI S.A'!U12 -> -6313.3345 | F42: ='CEI S.A'!U21 -> -721.1934 | H42: =F42/D42 -> 0.11423336
C43: ='CEI S.F'!C3 -> CEI São Franscisco | D43: ='CEI S.F'!U12 -> -8149.0966 | F43: ='CEI S.F'!U21 -> -1854.3617 | H43: =F43/D43 -> 0.22755427
C44: ='CEI S.G'!C3 -> CEI São Geraldo | D44: ='CEI S.G'!U12 -> -18768.632 | F44: ='CEI S.G'!U21 -> -4579.14 | H44: =F44/D44 -> 0.24397836
C45: =AVANÇAR!C3 -> Avançar | D45: =AVANÇAR!U12 -> -144016.75 | F45: =AVANÇAR!U21 -> -6762.9658 | H45: =F45/D45 -> 0.046959577
C46: ='CEI C.M'!C3 -> CEI Coração de Mária | D46: ='CEI C.M'!U12 -> -7498.2023 | F46: ='CEI C.M'!U21 -> -2902.582 | H46: =F46/D46 -> 0.38710372
C47: Total | D47: =SUM(D22:D46) -> -12317233 | F47: =SUM(F22:F46) -> -6634232.3 | H47: =F47/D47 -> 0.53861387
C51: CUSTOS FIXOS E VARIÁVEIS
C54: Descrição
C55: =HSI!B9 -> CCEE - Câmara de Comercialização de Energia Elétrica
C56: =HSI!B20 -> CONTRATO Nº VI5/LP 018/19 (ENEL)
...

Sheet HSI
C3: HOSPITAL SANTA IZABEL
C5: Previsão de Consumo | H5: 1252.6588 | I5: 1155.0675 | J5: 1245.8238 | K5: 1235.8507 | L5: 1168.8182 | M5: 1080.5639 | N5: 1067.3378 | O5: 1084.5959 | P5: 1088.5 | Q5: 1095.6 | R5: 1110.5 | S5: 1150.4
B7: CONTRATOS | D7: BASE | E7: REAJUSTE | F7: Tarifa Out.2025 | G7: Tarifa 2026 (pós reajuste) | H7: 46023 | I7: 46054 | J7: 46082 | K7: 46113 | L7: 46143 | M7: 46174 | N7: 46204 | O7: 46235 | P7: 46266 | Q7: 46296 | R7: 46327 | S7: 46357 | U7: Total
B8: CONTRATO Nº VI5/LP 018/19 (ENEL) | D8: Janeiro | E8: IPCA | F8: 206 | G8: =F8*1.001 -> 206.206 | H8: 245547.71 | I8: 225443.91 | J8: 244139.71 | K8: 242339.82 | L8: 241017.32 | M8: 222818.75 | N8: 220091.46 | O8: 223650.18 | P8: 224455.23 | Q8: 225919.29 | R8: 228991.76 | S8: 237219.38 | U8: =SUM(H8:S8) -> 2781634.5
B9: CCEE - Câmara de Comercialização de Energia Elétrica | D9: - | E9: - | F9: - | G9: - | H9: 25000 | I9: 25000 | J9: 25000 | K9: 25000 | L9: 25000 | M9: 25000 | N9: 25000 | O9: 25000 | P9: 25000 | Q9: 25000 | R9: 25000 | S9: 25000 | U9: =SUM(H9:S9) -> 300000
B10: ENEL Trading (Energia Curto Prazo) | D10: - | E10: - | F10: - | G10: - | H10: 12500 | I10: 12500 | J10: 12500 | K10: 12500 | L10: 0 | M10: 0 | N10: 0 | O10: 0 | P10: 0 | Q10: 0 | R10: 0 | S10: 0 | U10: =SUM(H10:S10) -> 50000
B11: CONTRATO COELBA Nº 097/CCER/CCO/08/2012 | D11: Abril | E11: IPCA + ANEEL | F11: 272.5 | G11: =F11*(1+#REF!+#REF!) -> #REF! | H11: 341349.53 | I11: 314755.91 | J11: 339487 | K11: 358154.16 | L11: 338727.9 | M11: 313151.46 | N11: 309318.5 | O11: 314319.95 | P11: 315451.38 | Q11: 317508.99 | R11: 321827.06 | S11: 333390.23 | U11: =SUM(H11:S11) -> 3917442.1
B12: TOTAL GERAL | H12: =SUM(H8:H11) -> 624397.24 | I12: =SUM(I8:I11) -> 577699.82 | J12: =SUM(J8:J11) -> 621126.71 | K12: =SUM(K8:K11) -> 637993.98 | L12: =SUM(L8:L11) -> 604745.22 | M12: =SUM(M8:M11) -> 560970.21 | N12: =SUM(N8:N11) -> 554409.96 | O12: =SUM(O8:O11) -> 562970.13 | ... S12: =SUM(S8:S11) -> 595609.62 | U12: =SUM(U8:U11)*-1 -> -7049076.6
C14: REALIZADO
C15: Organizado por data de emissão das NF's
C17: Consumo Real | H17: =1125702.08/1000 -> 1125.7021 | I17: 1101.56 | J17: 1258.58 | K17: 1215.33 | L17: 1224.16
B19: CONTRATOS | H19: 46023 | I19: 46054 | J19: 46082 | K19: 46113 | L19: 46143 | M19: 46174 | N19: 46204 | O19: 46235 | P19: 46266 | Q19: 46296 | R19: 46327 | S19: 46357 | U19: Total
B20: CONTRATO Nº VI5/LP 018/19 (ENEL) | H20: =224790.69+26238.07 -> 251028.76 | I20: =209871.3+29811.2 -> 239682.5 | J20: =27025.22+194502.94 -> 221528.16 | K20: =209180.26+31056.74 -> 240237 | L20: =211942.72+29925.4 -> 241868.12 | M20: =30078.76+213173.36 -> 243252.12 | N20: =196882.39+25973.61 -> 222856 | U20: =SUM(H20:S20) -> 1660452.7
B21: CCEE - Câmara de Comercialização de Energia Elétrica | G21: 24823.01 | H21: 24823.01 | I21: 31721.14 | J21: 39522.64 | K21: 2289 | L21: 10691.57 | M21: 39754.6 | U21: =SUM(H21:S21) -> 148801.96
B22: ENEL Trading (Energia Curto Prazo) | H22: 47129.08 | I22: 20115.67 | J22: 20077.46 | K22: 35098.37 | L22: 12223.43 | M22: 14129.34 | N22: 0 | U22: =SUM(H22:S22) -> 148773.35
B23: CONTRATO COELBA Nº 097/CCER/CCO/08/2012 | H23: 342652.08 | I23: =344909.01 -> 344909.01 | J23: 361129.53 | K23: 369682.31 | L23: 0 | M23: =433031.01+411075.54 -> 844106.55 | U23: =SUM(H23:S23) -> 2262479.5
B24: TOTAL GERAL | H24: =SUM(H20:H23) -> 665632.93 | I24: =SUM(I20:I23) -> 636428.32 | J24: =SUM(J20:J23) -> 642257.79 | K24: =SUM(K20:K23) -> 647306.68 | L24: =SUM(L20:L23) -> 264783.12 | M24: =SUM(M20:M23) -> 1141242.6 | N24: =SUM(N20:N23) -> 222856 | O24: =SUM(O20:O23) -> 0 | ... S24: =SUM(S20:S23) -> 0 | U24: =SUM(U20:U23)*-1 -> -4220507.5
B26: Diferença | H26: =H24/H12 -> 1.0660408 | I26: =I24/I12 -> 1.1016592 | J26: =J24/J12 -> 1.0340206 | K26: =K24/K12 -> 1.0145968 | L26: =L24/L12 -> 0.43784244 | M26: =M24/M12 -> 2.0344086 | N26: =N24/N12 -> 0.40196969 | O26: =O24/O12 -> 0 | ... S26: =S24/S12 -> 0

Sheet Pupileira
C3: PUPILEIRA
C5: Previsão de Consumo | H5: 63.55117 | I5: 61.67968 | J5: 67.36165 | K5: 68.29146 | L5: 59.10687 | M5: 49.34063 | N5: 46.16675 | O5: 51.34238 | P5: 55.5 | Q5: 58.6 | R5: 60.5 | S5: 62.4
B7: CONTRATOS | D7: BASE | E7: REAJUSTE | F7: Tarifa Out.2025 | G7: Tarifa 2026 (pós reajuste) | H7: 46023 | I7: 46054 | J7: 46082 | K7: 46113 | L7: 46143 | M7: 46174 | N7: 46204 | O7: 46235 | P7: 46266 | Q7: 46296 | R7: 46327 | S7: 46357 | U7: Total
B8: CONTRATO Nº VI5/LP 018/19 (ENEL) | D8: Janeiro | E8: IPCA | F8: 206 | G8: =F8*1.001 -> 206.206 | H8: 11604.633 | I8: 11218.72 | J8: 12390.376 | K8: 12582.109 | L8: 12188.191 | M8: 10174.334 | N8: 9519.8609 | O8: 10587.107 | P8: 11444.433 | Q8: 12083.672 | R8: 12475.463 | S8: 12867.254 | U8: =SUM(H8:S8) -> 139136.15
B9: CCEE - Câmara de Comercialização de Energia Elétrica | D9: - | E9: - | F9: - | G9: - | H9: 1000 | I9: 1000 | J9: 1000 | K9: 1000 | L9: 1000 | M9: 1000 | N9: 1000 | O9: 1000 | P9: 1000 | Q9: 1000 | R9: 1000 | S9: 1000 | U9: =SUM(H9:S9) -> 12000
B10: ENEL Trading (Energia Curto Prazo) | D10: - | E10: - | F10: - | G10: - | H10: 1500 | I10: 1500 | J10: 1500 | K10: 1500 | L10: 0 | M10: 0 | N10: 0 | O10: 0 | P10: 0 | Q10: 0 | R10: 0 | S10: 0 | U10: =SUM(H10:S10) -> 6000
B11: CONTRATO COELBA | D11: Abril | E11: IPCA + ANEEL | F11: 272.5 | G11: =F11*(1+#REF!+#REF!) -> #REF! | H11: 26500.838 | I11: 25720.427 | J11: 28089.808 | K11: 30285.863 | L11: 26212.685 | M11: 21881.558 | N11: 20474.007 | O11: 22769.293 | P11: 24613.112 | Q11: 25987.899 | R11: 26830.51 | S11: 27673.121 | U11: =SUM(H11:S11) -> 307039.12
B12: TOTAL GERAL | H12: =SUM(H8:H11) -> 40605.47 | I12: =SUM(I8:I11) -> 39439.147 | J12: =SUM(J8:J11) -> 42980.184 | K12: =SUM(K8:K11) -> 45367.971 | L12: =SUM(L8:L11) -> 39400.876 | M12: =SUM(M8:M11) -> 33055.892 | N12: =SUM(N8:N11) -> 30993.868 | O12: =SUM(O8:O11) -> 34356.4 | ... S12: =SUM(S8:S11) -> 41540.375 | U12: =SUM(U8:U11)*-1 -> -464175.27
C14: Consumo Real | H14: =59571.46/1000 -> 59.57146 | I14: =(51245.87+4868.15)/1000 -> 56.11402 | J14: 80.08 | K14: 65.52 | L14: 65.46
B16: CONTRATOS | H16: 46023 | I16: 46054 | J16: 46082 | K16: 46113 | L16: 46143 | M16: 46174 | N16: 46204 | O16: 46235 | P16: 46266 | Q16: 46296 | R16: 46327 | S16: 46357 | U16: Total
B17: CONTRATO Nº VI5/LP 018/19 (ENEL) | H17: =10376.64+1211.28 -> 11587.92 | I17: =10328.28+1467.15 -> 11795.43 | J17: =9916.06+1377.84 -> 11293.9 | K17: =1982.95+13355.6 -> 15338.55 | L17: =11384.29+1607.45 -> 12991.74 | M17: =11396.96+1608.15 -> 13005.11 | N17: =9431.45+1244.32 -> 10675.77 | U17: =SUM(I17:S17) -> 75100.5
B18: ENEL Trading (Energia Curto Prazo) | H18: 2175.42 | I18: 990.02 | J18: 1023.68 | K18: 2241.07 | L18: 656.64 | M18: 755.51 | N18: 0 | U18: =SUM(I18:S18) -> 5666.92
B19: CONTRATO COELBA | H19: 32782.18 | I19: 25290.54 | J19: 25996.55 | K19: 39225.4 | L19: 33685.26 | M19: 36193.92 | U19: =SUM(I19:S19) -> 160391.67
B20: TOTAL GERAL | H20: =SUM(H17:H19) -> 46545.52 | I20: =SUM(I17:I19) -> 38075.99 | J20: =SUM(J17:J19) -> 38314.13 | K20: =SUM(K17:K19) -> 56805.02 | L20: =SUM(L17:L19) -> 47333.64 | M20: =SUM(M17:M19) -> 49954.54 | N20: =SUM(N17:N19) -> 10675.77 | O20: =SUM(O17:O19) -> 0 | ... S20: =SUM(S17:S19) -> 0 | U20: =SUM(U17:U19)*-1 -> -241159.09
B22: Diferença | H22: =H20/H12 -> 1.1462869 | I22: =I20/I12 -> 0.96543646 | J22: =J20/J12 -> 0.89143708 | K22: =K20/K12 -> 1.2520952 | L22: =L20/L12 -> 1.2013347 | M22: =M20/M12 -> 1.5112144 | N22: =N20/N12 -> 0.34444781 | O22: =O20/O12 -> 0 | ... S22: =S20/S12 -> 0

Sheet Anexo HSI
C3: ANEXO HSI
C5: Previsão de Consumo | H5: 46.74229 | I5: 44.96974 | J5: 48.82036 | K5: 49.70969 | L5: 44.91312 | M5: 40.56475 | N5: 39.52957 | O5: 39.67024 | P5: 45.45 | Q5: 48.5 | R5: 49.55 | S5: 45.29
B7: CONTRATOS | D7: BASE | E7: REAJUSTE | F7: Tarifa Out.2025 | G7: Tarifa 2026 (pós reajuste) | H7: 46023 | I7: 46054 | J7: 46082 | K7: 46113 | L7: 46143 | M7: 46174 | N7: 46204 | O7: 46235 | P7: 46266 | Q7: 46296 | R7: 46327 | S7: 46357 | U7: Total
B8: CONTRATO Nº VI5/LP 018/19 (ENEL) | D8: Janeiro | E8: IPCA | F8: 206 | G8: =F8*1.001 -> 206.206 | H8: 8378.9117 | I8: 8013.7664 | J8: 8806.9942 | K8: 8990.1961 | L8: 9261.3548 | M8: 8364.6948 | N8: 8151.2345 | O8: 8180.2415 | P8: 9372.0627 | Q8: 10000.991 | R8: 10217.507 | S8: 9339.0697 | U8: =SUM(H8:S8) -> 107077.02
B9: CCEE - Câmara de Comercialização de Energia Elétrica | D9: - | E9: - | F9: - | G9: - | H9: 500 | I9: 500 | J9: 500 | K9: 500 | L9: 500 | M9: 500 | N9: 500 | O9: 500 | P9: 500 | Q9: 500 | R9: 500 | S9: 500 | U9: =SUM(H9:S9) -> 6000
B10: ENEL Trading (Energia Curto Prazo) | D10: - | E10: - | F10: - | G10: - | H10: 1250 | I10: 1250 | J10: 1250 | K10: 1250 | L10: 0 | M10: 0 | N10: 0 | O10: 0 | P10: 0 | Q10: 0 | R10: 0 | S10: 0 | U10: =SUM(H10:S10) -> 5000
B11: CONTRATO COELBA | D11: Abril | E11: IPCA + ANEEL | F11: 272.5 | G11: =F11*(1+#REF!+#REF!) -> #REF! | H11: 17373.794 | I11: 16714.949 | J11: 18146.198 | K11: 19280.495 | L11: 17420.088 | M11: 15733.521 | N11: 15332.014 | O11: 15386.575 | P11: 17628.324 | Q11: 18811.302 | R11: 19218.557 | S11: 17566.266 | U11: =SUM(H11:S11) -> 208612.08
B12: TOTAL GERAL | H12: =SUM(H8:H11) -> 27502.705 | I12: =SUM(I8:I11) -> 26478.715 | J12: =SUM(J8:J11) -> 28703.192 | K12: =SUM(K8:K11) -> 30020.691 | L12: =SUM(L8:L11) -> 27181.443 | M12: =SUM(M8:M11) -> 24598.216 | N12: =SUM(N8:N11) -> 23983.249 | O12: =SUM(O8:O11) -> 24066.816 | ... S12: =SUM(S8:S11) -> 27405.335 | U12: =SUM(U8:U11)*-1 -> -326689.11
C14: Consumo Real | H14: 48.25635 | I14: 46.61401 | J14: 51.07427 | K14: 47.30176 | L14: 40.32655 | M14: =(30917.02+2007.39)/1000 -> 32.92441
B16: CONTRATOS | H16: 46023 | I16: 46054 | J16: 46082 | K16: 46113 | L16: 46143 | M16: 46174 | N16: 46204 | O16: 46235 | P16: 46266 | Q16: 46296 | R16: 46327 | S16: 46357 | U16: Total
B17: CONTRATO Nº VI5/LP 018/19 (ENEL) | H17: =7624.94+889.95 -> 8514.89 | I17: =1184.79+8341.07 -> 9525.86 | J17: =8242.9+1145.27 -> 9388.17 | K17: =1291.5+8698.52 -> 9990.02 | L17: =8238.18+1163.2 -> 9401.38 | M17: =987.03+6994.86 -> 7981.89 | N17: =6089.22+803.38 -> 6892.6 | U17: =SUM(I17:S17) -> 53179.92
B18: ENEL Trading (Energia Curto Prazo) | H18: 1598.62 | I18: 799.47 | J18: 850.78 | K18: 1459.37 | L18: 474.9 | M18: 463.62 | N18: 0 | U18: =SUM(I18:S18) -> 4048.14
B19: CONTRATO COELBA | H19: 17837.66 | I19: 17447.13 | J19: 18943.98 | K19: 19531.67 | L19: 19628.35 | M19: 16994.38 | N19: 14876.12 | U19: =SUM(I19:S19) -> 107421.63
B20: TOTAL GERAL | H20: =SUM(H17:H19) -> 27951.17 | I20: =SUM(I17:I19) -> 27772.46 | J20: =SUM(J17:J19) -> 29182.93 | K20: =SUM(K17:K19) -> 30981.06 | L20: =SUM(L17:L19) -> 29504.63 | M20: =SUM(M17:M19) -> 25439.89 | N20: =SUM(N17:N19) -> 21768.72 | O20: =SUM(O17:O19) -> 0 | ... S20: =SUM(S17:S19) -> 0 | U20: =SUM(U17:U19)*-1 -> -164649.69
B22: Diferença | H22: =H20/H12 -> 1.0163062 | I22: =I20/I12 -> 1.0488598 | J22: =J20/J12 -> 1.0167137 | K22: =K20/K12 -> 1.0319902 | L22: =L20/L12 -> 1.0854696 | M22: =M20/M12 -> 1.0342169 | N22: =N20/N12 -> 0.90766352 | O22: =O20/O12 -> 0 | ... S22: =S20/S12 -> 0

Sheet HMS
C3: HOSPITAL MUNICIPAL DE SALVADOR
C5: Previsão de Consumo | H5: 472 | I5: 420 | J5: 473 | K5: 488 | L5: 452 | M5: 400 | N5: 385 | O5: 391 | P5: 366 | Q5: 450 | R5: 415 | S5: 477
B7: CONTRATOS | D7: BASE | E7: REAJUSTE | F7: Tarifa Out.2025 | G7: Tarifa 2026 (pós reajuste) | H7: 46023 | I7: 46054 | J7: 46082 | K7: 46113 | L7: 46143 | M7: 46174 | N7: 46204 | O7: 46235 | P7: 46266 | Q7: 46296 | R7: 46327 | S7: 46357 | U7: Total
B8: Coelba (Consumo de Energia) | D8: Janeiro | E8: IPCA | F8: 206 | G8: =F8*1.001 -> 206.206 | H8: 146792 | I8: 130620 | J8: 147103 | K8: 158369.91 | L8: 146686.88 | M8: 129811.4 | N8: 124943.47 | O8: 126890.64 | P8: 118777.43 | Q8: 146037.83 | R8: 134679.33 | S8: 154800.09 | U8: =SUM(H8:S8) -> 1665512
B9: CONTRATO ENEL - ACL (Venc. Abr) | D9: - | E9: - | F9: - | G9: - | H9: 69950.4 | I9: 62244 | J9: 70098.6 | K9: 72321.6 | U9: =SUM(H9:S9) -> 274614.6
B10: CONTRATO ENEL - ACL (Após Abr.) | D10: - | E10: - | F10: - | G10: - | H10: - | I10: - | J10: - | K10: - | L10: 115260 | M10: 102000 | N10: 98175 | O10: 99705 | P10: 93330 | Q10: 114750 | R10: 105825 | S10: 121635 | U10: =SUM(H10:S10) -> 850680
B11: CCEE - Câmara de Comercialização de Energia Elétrica | D11: Abril | E11: IPCA + ANEEL | F11: 272.5 | G11: =F11*(1+#REF!+#REF!) -> #REF! | H11: 8000 | I11: 8000 | J11: 8000 | K11: 8000 | L11: 8000 | M11: 8000 | N11: 8000 | O11: 8000 | P11: 8000 | Q11: 8000 | R11: 8000 | S11: 8000 | U11: =SUM(H11:S11) -> 96000
B12: TOTAL GERAL | H12: =SUM(H8:H11) -> 224742.4 | I12: =SUM(I8:I11) -> 200864 | J12: =SUM(J8:J11) -> 225201.6 | K12: =SUM(K8:K11) -> 238691.51 | L12: =SUM(L8:L11) -> 269946.88 | M12: =SUM(M8:M11) -> 239811.4 | N12: =SUM(N8:N11) -> 231118.47 | O12: =SUM(O8:O11) -> 234595.64 | ... S12: =SUM(S8:S11) -> 284435.09 | U12: =SUM(U8:U11)*-1 -> -2886806.6
C14: Consumo Real | H14: =488109.24/1000 -> 488.10924 | I14: 432.93 | J14: 498.12 | K14: 464.53 | L14: =(424977.48+37808.64)/1000 -> 462.78612
B16: CONTRATOS | D16: BASE | E16: REAJUSTE | F16: Tarifa Out.2025 | G16: Tarifa 2026 (pós reajuste) | H16: 46023 | I16: 46054 | J16: 46082 | K16: 46113 | L16: 46143 | M16: 46174 | N16: 46204 | O16: 46235 | P16: 46266 | Q16: 46296 | R16: 46327 | S16: 46357 | U16: Total
B17: Coelba (Consumo de Energia) | D17: Janeiro | E17: IPCA | F17: 206 | G17: =F17*1.001 -> 206.206 | H17: 149675.55 | I17: 153536.82 | J17: 146410.12 | K17: 157944.62 | L17: 162241.05 | M17: 176534.97 | U17: =SUM(I17:S17) -> 796667.58
B18: CONTRATO ENEL - ACL (Venc. Abr) | D18: - | E18: - | F18: - | G18: - | H18: 68692.34 | I18: 88637.68 | J18: 78499.63 | K18: 90987.39 | L18: 88013.48 | M18: 0 | N18: 0 | O18: 0 | P18: 0 | Q18: 0 | R18: 0 | S18: 0 | U18: =SUM(I18:S18) -> 346138.18
B19: CONTRATO AXIA - ACL (Após Abr.) | D19: - | E19: - | F19: - | G19: - | I19: 0 | J19: 0 | K19: 0 | M19: 132199.64 | N19: 115908 | U19: =SUM(I19:S19) -> 248107.64
B20: CCEE - Câmara de Comercialização de Energia Elétrica | D20: Abril | E20: IPCA + ANEEL | F20: 272.5 | G20: =F20*(1+#REF!+#REF!) -> #REF! | H20: 4810.04 | I20: 12100.08 | J20: 12901.9 | K20: 12229.99 | L20: 8451.16 | M20: 12806.92 | N20: 71376.93 | U20: =SUM(I20:S20) -> 129866.98
B21: TOTAL GERAL | H21: =SUM(H17:H20) -> 223177.93 | I21: =SUM(I17:I20) -> 254274.58 | J21: =SUM(J17:J20) -> 237811.65 | K21: =SUM(K17:K20) -> 261162 | L21: =SUM(L17:L20) -> 258705.69 | M21: =SUM(M17:M20) -> 321541.53 | N21: =SUM(N17:N20) -> 187284.93 | O21: =SUM(O17:O20) -> 0 | ... S21: =SUM(S17:S20) -> 0 | U21: =SUM(U17:U20)*-1 -> -1520780.4
B23: Diferença | H23: =H21/H12 -> 0.99303883 | I23: =I21/I12 -> 1.2659042 | J23: =J21/J12 -> 1.0559945 | K23: =K21/K12 -> 1.0941403 | L23: =L21/L12 -> 0.95835776 | M23: =M21/M12 -> 1.34081 | N23: =N21/N12 -> 0.81034167 | O23: =O21/O12 -> 0 | ... S23: =S21/S12 -> 0 | U23: =U21/U12 -> 0.5268037

Sheet Curativos Especiais
C3: Curativos Especiais
C5: Consumo (kWh) | E5: Previsão de Consumo (kWh) | G5: ='[1]Rateio UFV - Faturamento (R$)'!G82 -> -1469.9318 | H5: 8070 | I5: 8070 | J5: 8070 | K5: 8070 | L5: 8070 | M5: 8400 | N5: 8040 | O5: 7840 | P5: 8000 | Q5: 8070 | R5: 8070 | S5: 8070
B7: Despesa | D7: Tarifa Out.25 (R$/kWh) | E7: BASE | F7: REAJUSTE | G7: Tarifa + Reajuste | H7: 46023 | I7: 46054 | J7: 46082 | K7: 46113 | L7: 46143 | M7: 46174 | N7: 46204 | O7: 46235 | P7: 46266 | Q7: 46296 | R7: 46327 | S7: 46357 | U7: Total
C8: Coelba | D8: ='[1]Rateio UFV - Faturamento (R$)'!H81 -> 7646.94 | E8: Abril | F8: IPCA + ANEEL | G8: =D8*(1+#REF!) -> #REF! | H8: 9441.9 | I8: 9441.9 | J8: 9441.9 | K8: 9852.6226 | L8: 9852.6226 | M8: 10255.518 | N8: 9815.9958 | O8: 9571.8168 | P8: 9767.16 | Q8: 9852.6226 | R8: 9852.6226 | S8: 9852.6226 | U8: =SUM(H8:S8) -> 116999.3
B9: TOTAL GERAL | H9: =SUM(H8) -> 9441.9 | I9: =SUM(I8) -> 9441.9 | J9: =SUM(J8) -> 9441.9 | K9: =SUM(K8) -> 9852.6226 | L9: =SUM(L8) -> 9852.6226 | M9: =SUM(M8) -> 10255.518 | N9: =SUM(N8) -> 9815.9958 | O9: =SUM(O8) -> 9571.8168 | ... S9: =SUM(S8) -> 9852.6226 | U9: =SUM(U8)*-1 -> -116999.3
C12: Consumo (kWh) | E12: Previsão de Consumo (kWh) | G12: ='[1]Rateio UFV - Faturamento (R$)'!G89 -> 0 | H12: 16360 | I12: 13560 | J12: 11440 | K12: 10560 | L12: 10560 | M12: 10320 | N12: 10560
B14: Despesa | D14: Tarifa Out.25 (R$/kWh) | E14: BASE | F14: REAJUSTE | G14: Tarifa + Reajuste | H14: 46023 | I14: 46054 | J14: 46082 | K14: 46113 | L14: 46143 | M14: 46174 | N14: 46204 | O14: 46235 | P14: 46266 | Q14: 46296 | R14: 46327 | S14: 46357 | U14: Total
C15: Coelba | D15: ='[1]Rateio UFV - Faturamento (R$)'!H88 -> 0 | E15: Abril | F15: IPCA + ANEEL | G15: =D15*(1+#REF!) -> #REF! | H15: 18228 | I15: 14905.8 | J15: 12597.55 | K15: 11764.91 | L15: 12331.38 | M15: 12377.08 | N15: 12609.77 | O15: 0 | P15: 0 | Q15: 0 | R15: 0 | S15: 0 | U15: =SUM(H15:S15) -> 94814.49
B16: TOTAL GERAL | H16: =SUM(H15) -> 18228 | I16: =SUM(I15) -> 14905.8 | J16: =SUM(J15) -> 12597.55 | K16: =SUM(K15) -> 11764.91 | L16: =SUM(L15) -> 12331.38 | M16: =SUM(M15) -> 12377.08 | N16: =SUM(N15) -> 12609.77 | O16: =SUM(O15) -> 0 | ... S16: =SUM(S15) -> 0 | U16: =SUM(U15)*-1 -> -94814.49
B18: Diferença | H18: =H16/H9 -> 1.9305436 | I18: =I16/I9 -> 1.5786865 | J18: =J16/J9 -> 1.3342177 | K18: =K16/K9 -> 1.1940892 | L18: =L16/L9 -> 1.2515835 | M18: =M16/M9 -> 1.2068703 | N18: =N16/N9 -> 1.2846144 | O18: =O16/O9 -> 0 | ... S18: =S16/S9 -> 0 | U18: =U16/U9 -> 0.81038508

Sheet Casa de Apoio Solange Fraga
C3: Casa de Apoio Solange Fraga
C5: Consumo (kWh) | E5: Previsão de Consumo (kWh) | G5: ='[1]Rateio UFV - Faturamento (R$)'!G82 -> -1469.9318 | H5: 1939 | I5: 2621 | J5: 1994 | K5: 2409 | L5: 2604 | M5: 2188 | N5: 1637 | O5: 1790 | P5: 1530 | Q5: 2462 | R5: 2151 | S5: 1881
B7: Despesa | D7: Tarifa Out.25 (R$/kWh) | E7: BASE | F7: REAJUSTE | G7: Tarifa + Reajuste | H7: 46023 | I7: 46054 | J7: 46082 | K7: 46113 | L7: 46143 | M7: 46174 | N7: 46204 | O7: 46235 | P7: 46266 | Q7: 46296 | R7: 46327 | S7: 46357 | U7: Total
C8: Coelba | D8: ='[1]Rateio UFV - Faturamento (R$)'!H81 -> 7646.94 | E8: Abril | F8: IPCA + ANEEL | G8: =D8*(1+#REF!) -> #REF! | H8: 2690.3625 | I8: 3636.6375 | J8: 2766.675 | K8: 3571.4479 | L8: 3860.5439 | M8: 3243.8057 | N8: 2426.9241 | O8: 2653.7533 | P8: 2268.2919 | Q8: 3650.0227 | R8: 3188.9516 | S8: 2788.6648 | U8: =SUM(H8:S8) -> 36746.081
C9: Rateio Guanambi | H9: 0 | I9: 0 | J9: 0 | K9: 0 | L9: 0 | M9: 0 | N9: 0 | O9: 0 | P9: 0 | Q9: 0 | R9: 0 | S9: 0 | U9: =SUM(H9:S9) -> 0
B10: TOTAL GERAL | H10: =SUM(H8) -> 2690.3625 | I10: =SUM(I8) -> 3636.6375 | J10: =SUM(J8) -> 2766.675 | K10: =SUM(K8) -> 3571.4479 | L10: =SUM(L8) -> 3860.5439 | M10: =SUM(M8) -> 3243.8057 | N10: =SUM(N8) -> 2426.9241 | O10: =SUM(O8) -> 2653.7533 | ... S10: =SUM(S8) -> 2788.6648 | U10: =SUM(U8:U9)*-1 -> -36746.081
C13: Consumo (kWh) | E13: Previsão de Consumo (kWh) | G13: ='[1]Rateio UFV - Faturamento (R$)'!G89 -> 0 | H13: 1732 | I13: 1709 | J13: 2163 | K13: 2217 | L13: 1812 | M13: 1660
B15: Despesa | D15: Tarifa Out.25 (R$/kWh) | E15: BASE | F15: REAJUSTE | G15: Tarifa + Reajuste | H15: 46023 | I15: 46054 | J15: 46082 | K15: 46113 | L15: 46143 | M15: 46174 | N15: 46204 | O15: 46235 | P15: 46266 | Q15: 46296 | R15: 46327 | S15: 46357 | U15: Total
C16: Coelba | D16: ='[1]Rateio UFV - Faturamento (R$)'!H88 -> 0 | E16: Abril | F16: IPCA + ANEEL | G16: =D16*(1+#REF!) -> #REF! | H16: 2499.18 | I16: 2428.49 | J16: 2977.31 | K16: 2217 | L16: 2675.32 | M16: 2542.68 | N16: 0 | O16: 0 | P16: 0 | Q16: 0 | R16: 0 | S16: 0 | U16: =SUM(H16:S16) -> 15339.98
C17: Rateio Guanambi | H17: 0 | I17: 0 | J17: 0 | K17: 0 | L17: 0 | M17: 0 | N17: 0 | O17: 0 | P17: 0 | Q17: 0 | R17: 0 | S17: 0 | U17: =SUM(H17:S17) -> 0
B18: TOTAL GERAL | H18: =SUM(H16) -> 2499.18 | I18: =SUM(I16) -> 2428.49 | J18: =SUM(J16) -> 2977.31 | K18: =SUM(K16) -> 2217 | L18: =SUM(L16) -> 2675.32 | M18: =SUM(M16) -> 2542.68 | N18: =SUM(N16) -> 0 | O18: =SUM(O16) -> 0 | ... S18: =SUM(S16) -> 0 | U18: =SUM(U16:U17)*-1 -> -15339.98
B20: Diferença | H20: =H18/H10 -> 0.92893801 | I20: =I18/I10 -> 0.66778446 | J20: =J18/J10 -> 1.0761329 | K20: =K18/K10 -> 0.62075664 | L20: =L18/L10 -> 0.69299043 | M20: =M18/M10 -> 0.78385705 | N20: =N18/N10 -> 0 | O20: =O18/O10 -> 0 | ... S20: =S18/S10 -> 0 | U20: =U18/U10 -> 0.41745894

Sheet Infanto Juvenil
C3: Unidade de Acolhimento Infanto Juvenil
C5: Consumo (kWh) | E5: Previsão de Consumo (kWh) | G5: ='[1]Rateio UFV - Faturamento (R$)'!G82 -> -1469.9318 | H5: 637 | I5: 753 | J5: 655 | K5: 634 | L5: 586 | M5: 441 | N5: 376 | O5: 395 | P5: 402 | Q5: 467 | R5: 547 | S5: 585
B7: Despesa | D7: Tarifa Out.25 (R$/kWh) | E7: BASE | F7: REAJUSTE | G7: Tarifa + Reajuste | H7: 46023 | I7: 46054 | J7: 46082 | K7: 46113 | L7: 46143 | M7: 46174 | N7: 46204 | O7: 46235 | P7: 46266 | Q7: 46296 | R7: 46327 | S7: 46357 | U7: Total
C8: Coelba | D8: ='[1]Rateio UFV - Faturamento (R$)'!H81 -> 7646.94 | E8: Abril | F8: IPCA + ANEEL | G8: =D8*(1+#REF!) -> #REF! | H8: 751.66 | I8: 888.54 | J8: 772.9 | K8: 799.36622 | L8: 738.84638 | M8: 556.02603 | N8: 474.07208 | O8: 498.02785 | P8: 506.85366 | Q8: 588.80761 | R8: 689.67401 | S8: 737.58555 | U8: =SUM(H8:S8) -> 8002.3594
B9: TOTAL GERAL | H9: =SUM(H8) -> 751.66 | I9: =SUM(I8) -> 888.54 | J9: =SUM(J8) -> 772.9 | K9: =SUM(K8) -> 799.36622 | L9: =SUM(L8) -> 738.84638 | M9: =SUM(M8) -> 556.02603 | N9: =SUM(N8) -> 474.07208 | O9: =SUM(O8) -> 498.02785 | ... S9: =SUM(S8) -> 737.58555 | U9: =SUM(U8)*-1 -> -8002.3594
C12: Consumo (kWh) | E12: Previsão de Consumo (kWh) | G12: ='[1]Rateio UFV - Faturamento (R$)'!G89 -> 0 | H12: 712 | I12: 600 | J12: 712 | K12: 670 | L12: 611 | M12: 523
B14: Despesa | D14: Tarifa Out.25 (R$/kWh) | E14: BASE | F14: REAJUSTE | G14: Tarifa + Reajuste | H14: 46023 | I14: 46054 | J14: 46082 | K14: 46113 | L14: 46143 | M14: 46174 | N14: 46204 | O14: 46235 | P14: 46266 | Q14: 46296 | R14: 46327 | S14: 46357 | U14: Total
C15: Coelba | D15: ='[1]Rateio UFV - Faturamento (R$)'!H88 -> 0 | E15: Abril | F15: IPCA + ANEEL | G15: =D15*(1+#REF!) -> #REF! | H15: 920.84 | I15: 750.89 | J15: 901.77 | K15: 861.12 | L15: 805.42 | M15: 715.8 | U15: =SUM(H15:S15) -> 4955.84
B16: TOTAL GERAL | H16: =SUM(H15) -> 920.84 | I16: =SUM(I15) -> 750.89 | J16: =SUM(J15) -> 901.77 | K16: =SUM(K15) -> 861.12 | L16: =SUM(L15) -> 805.42 | M16: =SUM(M15) -> 715.8 | N16: =SUM(N15) -> 0 | O16: =SUM(O15) -> 0 | ... S16: =SUM(S15) -> 0 | U16: =SUM(U15)*-1 -> -4955.84
B18: Diferença | H18: =H16/H9 -> 1.2250752 | I18: =I16/I9 -> 0.84508295 | J18: =J16/J9 -> 1.1667357 | K18: =K16/K9 -> 1.0772534 | L18: =L16/L9 -> 1.0901048 | M18: =M16/M9 -> 1.2873498 | N18: =N16/N9 -> 0 | O18: =O16/O9 -> 0 | ... S18: =S16/S9 -> 0 | U18: =U16/U9 -> 0.61929735

Sheet Casa Lad.7
C3: Casa da Ladeira, 7 (Galpão de Obras)
C5: Consumo (kWh) | E5: Previsão de Consumo (kWh) | G5: ='[1]Rateio UFV - Faturamento (R$)'!G82 -> -1469.9318 | H5: 426 | I5: 478 | J5: 468 | K5: 411 | L5: 463 | M5: 469 | N5: 368 | O5: 413 | P5: 431 | Q5: 500 | R5: 541 | S5: 494
B7: Despesa | D7: Tarifa Out.25 (R$/kWh) | E7: BASE | F7: REAJUSTE | G7: Tarifa + Reajuste | H7: 46023 | I7: 46054 | J7: 46082 | K7: 46113 | L7: 46143 | M7: 46174 | N7: 46204 | O7: 46235 | P7: 46266 | Q7: 46296 | R7: 46327 | S7: 46357 | U7: Total
C8: Coelba | H8: 532.5 | I8: 597.5 | J8: 585 | K8: 548.94187 | L8: 618.39437 | M8: 626.40813 | N8: 491.51 | O8: 551.61312 | P8: 575.65437 | Q8: 667.8125 | R8: 722.57313 | S8: 659.79875 | U8: =SUM(H8:S8) -> 7177.7062
B9: TOTAL GERAL | H9: =SUM(H8) -> 532.5 | I9: =SUM(I8) -> 597.5 | J9: =SUM(J8) -> 585 | K9: =SUM(K8) -> 548.94187 | L9: =SUM(L8) -> 618.39437 | M9: =SUM(M8) -> 626.40813 | N9: =SUM(N8) -> 491.51 | O9: =SUM(O8) -> 551.61312 | ... S9: =SUM(S8) -> 659.79875 | U9: =SUM(U8)*-1 -> -7177.7062
C12: Consumo (kWh) | E12: Previsão de Consumo (kWh) | G12: ='[1]Rateio UFV - Faturamento (R$)'!G89 -> 0 | H12: 386 | I12: 434 | J12: 452 | K12: 452 | L12: 199
B14: Despesa | D14: Tarifa Out.25 (R$/kWh) | E14: BASE | F14: REAJUSTE | G14: Tarifa + Reajuste | H14: 46023 | I14: 46054 | J14: 46082 | K14: 46113 | L14: 46143 | M14: 46174 | N14: 46204 | O14: 46235 | P14: 46266 | Q14: 46296 | R14: 46327 | S14: 46357 | U14: Total
C15: Coelba | D15: ='[1]Rateio UFV - Faturamento (R$)'!H88 -> 0 | E15: Abril | F15: IPCA + ANEEL | G15: =D15*(1+#REF!) -> #REF! | H15: 545.54 | I15: 590.58 | J15: 733.95 | K15: 738.22 | M15: 279.81 | U15: =SUM(H15:S15) -> 2888.1
B16: TOTAL GERAL | H16: =SUM(H15) -> 545.54 | I16: =SUM(I15) -> 590.58 | J16: =SUM(J15) -> 733.95 | K16: =SUM(K15) -> 738.22 | L16: =SUM(M15) -> 279.81 | M16: =SUM(M15) -> 279.81 | N16: =SUM(N15) -> 0 | O16: =SUM(O15) -> 0 | P16: =SUM(P15) -> 0 | Q16: =SUM(Q15) -> 0 | R16: =SUM(R15) -> 0 | S16: =SUM(S15) -> 0 | U16: =SUM(U15)*-1 -> -2888.1
B18: Diferença | H18: =H16/H9 -> 1.0244883 | I18: =I16/I9 -> 0.98841841 | J18: =J16/J9 -> 1.2546154 | K18: =K16/K9 -> 1.3448054 | L18: =L16/L9 -> 0.45247824 | M18: =M16/M9 -> 0.44668961 | N18: =N16/N9 -> 0 | O18: =O16/O9 -> 0 | ... S18: =S16/S9 -> 0 | U18: =U16/U9 -> 0.40237088

Sheet Clínica Rio Vermelho
C3: Clínica Rio Vermelho
B5: Provisionado
C7: Consumo (kWh) | E7: Previsão de Consumo (kWh) | G7: ='[1]Rateio UFV - Faturamento (R$)'!G82 -> -1469.9318 | H7: 4019 | I7: 4624 | J7: 4252 | K7: 4688 | L7: 3443 | M7: 4205.2 | N7: 5130.33 | O7: 4337.3614 | P7: 4337.3614 | Q7: 4337.3614 | R7: 4337.3614 | S7: 4337.3614
B9: Despesa | D9: Tarifa Out.25 (R$/kWh) | E9: BASE | F9: REAJUSTE | G9: Tarifa + Reajuste | H9: 46023 | I9: 46054 | J9: 46082 | K9: 46113 | L9: 46143 | M9: 46174 | N9: 46204 | O9: 46235 | P9: 46266 | Q9: 46296 | R9: 46327 | S9: 46357 | U9: Total
C10: Coelba | H10: 5023.75 | I10: 5780 | J10: 5315 | K10: 6261.41 | L10: 4598.5569 | M10: 5616.5702 | N10: 6852.197 | O10: 5793.0884 | P10: 5793.0884 | Q10: 5793.0884 | R10: 5793.0884 | S10: 5793.0884 | U10: =SUM(H10:S10) -> 68412.926
C11: Rateio Guanambi | H11: 0 | I11: 0 | J11: 0 | K11: 0 | L11: 0 | M11: 0 | N11: 0 | O11: 0 | P11: 0 | Q11: 0 | R11: 0 | S11: 0 | U11: =SUM(H11:S11) -> 0
B12: TOTAL GERAL | H12: =SUM(H10) -> 5023.75 | I12: =SUM(I10) -> 5780 | J12: =SUM(J10) -> 5315 | K12: =SUM(K10) -> 6261.41 | L12: =SUM(L10) -> 4598.5569 | M12: =SUM(M10) -> 5616.5702 | N12: =SUM(N10) -> 6852.197 | O12: =SUM(O10) -> 5793.0884 | ... S12: =SUM(S10) -> 5793.0884 | U12: =SUM(U10:U11)*-1 -> -68412.926
B14: Realizado
C16: Consumo (kWh) | E16: Previsão de Consumo (kWh) | G16: ='[1]Rateio UFV - Faturamento (R$)'!G89 -> 0 | H16: =303.25+18.29+4461.46 -> 4783 | I16: 4269.636 | J16: 4830.78 | K16: 4363.2 | L16: 3894.828
B18: Despesa | D18: Tarifa Out.25 (R$/kWh) | E18: BASE | F18: REAJUSTE | G18: Tarifa + Reajuste | H18: 46023 | I18: 46054 | J18: 46082 | K18: 46113 | L18: 46143 | M18: 46174 | N18: 46204 | O18: 46235 | P18: 46266 | Q18: 46296 | R18: 46327 | S18: 46357 | U18: Total
C19: Coelba | D19: ='[1]Rateio UFV - Faturamento (R$)'!H88 -> 0 | E19: Abril | F19: IPCA + ANEEL | G19: =D19*(1+#REF!) -> #REF! | H19: 3340.02 | I19: 4704.4 | J19: 1469.56 | K19: 1460.1 | L19: 1489.47 | M19: 1512.84 | U19: =SUM(I19:S19) -> 10636.37
C20: Rateio Guanambi | H20: 3671.8032 | I20: 3671.8032 | J20: 3671.8032 | L20: 7522.3922 | M20: 3850.589 | N20: 0 | O20: 0 | P20: 0 | Q20: 0 | R20: 0 | S20: 0 | U20: =SUM(I20:S20) -> 18716.588
B21: TOTAL GERAL | H21: =SUM(H19:H20) -> 7011.8232 | I21: =SUM(I19:I20) -> 8376.2032 | J21: =SUM(J19:J20) -> 5141.3632 | K21: =SUM(K19:K20) -> 1460.1 | L21: =SUM(L19:L20) -> 9011.8622 | M21: =SUM(M19:M20) -> 5363.429 | N21: =SUM(N19:N20) -> 0 | O21: =SUM(O19:O20) -> 0 | ... S21: =SUM(S19:S20) -> 0 | U21: =SUM(U19:U20)*-1 -> -29352.958
B23: Diferença | H23: =H21/H12 -> 1.3957349 | I23: =I21/I12 -> 1.4491701 | J23: =J21/J12 -> 0.9673308 | K23: =K21/K12 -> 0.23319029 | L23: =L21/L12 -> 1.9597153 | M23: =M21/M12 -> 0.95492957 | N23: =N21/N12 -> 0 | O23: =O21/O12 -> 0 | ... S23: =S21/S12 -> 0 | U23: =U21/U12 -> 0.42905573

Sheet Clínica Ondina
C3: Clínica Ondina
B5: Provisionado
C7: Consumo (kWh) | E7: Previsão de Consumo (kWh) | G7: ='[1]Rateio UFV - Faturamento (R$)'!G82 -> -1469.9318 | H7: 4523 | I7: 4522.5867 | J7: 4522.5867 | K7: 4522.5867 | L7: 4522.5867 | M7: 4975.42 | N7: 4083.27 | O7: 4509.07 | P7: 4522.5867 | Q7: 4522.5867 | R7: 4522.5867 | S7: 4522.5867
B9: Despesa | D9: Tarifa Out.25 (R$/kWh) | E9: BASE | F9: REAJUSTE | G9: Tarifa + Reajuste | H9: 46023 | I9: 46054 | J9: 46082 | K9: 46113 | L9: 46143 | M9: 46174 | N9: 46204 | O9: 46235 | P9: 46266 | Q9: 46296 | R9: 46327 | S9: 46357 | U9: Total
C10: Coelba | H10: 5653.75 | I10: 5653.2333 | J10: 5653.2333 | K10: 6040.4798 | L10: 6040.4798 | M10: 6645.2953 | N10: 5453.7175 | O10: 6022.4266 | P10: 6040.4798 | Q10: 6040.4798 | R10: 6040.4798 | S10: 6040.4798 | U10: =SUM(H10:S10) -> 71324.535
C11: Rateio Guanambi | H11: 0 | I11: 0 | J11: 0 | K11: 0 | L11: 0 | M11: 0 | N11: 0 | O11: 0 | P11: 0 | Q11: 0 | R11: 0 | S11: 0 | U11: =SUM(H11:S11) -> 0
B12: TOTAL GERAL | H12: =SUM(H10) -> 5653.75 | I12: =SUM(I10) -> 5653.2333 | J12: =SUM(J10) -> 5653.2333 | K12: =SUM(K10) -> 6040.4798 | L12: =SUM(L10) -> 6040.4798 | M12: =SUM(M10) -> 6645.2953 | N12: =SUM(N10) -> 5453.7175 | O12: =SUM(O10) -> 6022.4266 | ... S12: =SUM(S10) -> 6040.4798 | U12: =SUM(U10:U11)*-1 -> -71324.535
B14: Realizado
C16: Consumo (kWh) | E16: Previsão de Consumo (kWh) | G16: ='[1]Rateio UFV - Faturamento (R$)'!G89 -> 0 | H16: =1199.8+408.75+4765.86 -> 6374.41 | I16: 5717.28 | J16: =6053.64+433.64+331.24 -> 6818.52 | K16: =6143.57 -> 6143.57 | L16: =5772.01 -> 5772.01
B18: Despesa | D18: Tarifa Out.25 (R$/kWh) | E18: BASE | F18: REAJUSTE | G18: Tarifa + Reajuste | H18: 46023 | I18: 46054 | J18: 46082 | K18: 46113 | L18: 46143 | M18: 46174 | N18: 46204 | O18: 46235 | P18: 46266 | Q18: 46296 | R18: 46327 | S18: 46357 | U18: Total
C19: Coelba | D19: ='[1]Rateio UFV - Faturamento (R$)'!H88 -> 0 | E19: Abril | F19: IPCA + ANEEL | G19: =D19*(1+#REF!) -> #REF! | H19: 4523.8 | I19: 4662.58 | J19: 437.03 | K19: 3506.06 | L19: 1452.88 | M19: 1461.62 | U19: =SUM(I19:S19) -> 11520.17
C20: Rateio Guanambi | H20: 3412.2255 | I20: 3413.2255 | J20: 3413.2255 | L20: 6992.6463 | M20: 3579.4208 | N20: 3579.4208 | U20: =SUM(I20:S20) -> 20977.939
B21: TOTAL GERAL | H21: =SUM(H19:H20) -> 7936.0255 | I21: =SUM(I19:I20) -> 8075.8055 | J21: =SUM(J19:J20) -> 3850.2555 | K21: =SUM(K19:K20) -> 3506.06 | L21: =SUM(L19:L20) -> 8445.5263 | M21: =SUM(M19:M20) -> 5041.0408 | N21: =SUM(N19:N20) -> 3579.4208 | O21: =SUM(O19:O20) -> 0 | ... S21: =SUM(S19:S20) -> 0 | U21: =SUM(U19:U20)*-1 -> -32498.109
B23: Diferença | H23: =H21/H12 -> 1.4036746 | I23: =I21/I12 -> 1.4285286 | J23: =J21/J12 -> 0.68107139 | K23: =K21/K12 -> 0.5804274 | L23: =L21/L12 -> 1.3981549 | M23: =M21/M12 -> 0.75858792 | N23: =N21/N12 -> 0.65632677 | O23: =O21/O12 -> 0 | ... S23: =S21/S12 -> 0 | U23: =U21/U12 -> 0.45563716
B25: Realizado (Vencimento)
B27: Despesa | D27: Tarifa Out.25 (R$/kWh) | E27: BASE | F27: REAJUSTE | G27: Tarifa + Reajuste | H27: 45931 | I27: 45962 | J27: 45992 | K27: 46023 | L27: 46054 | M27: 46082 | N27: 46113 | O27: 46143 | P27: 46174 | Q27: 46204 | R27: 46235 | S27: 46266 | U27: Total
C28: Coelba | D28: ='[1]Rateio UFV - Faturamento (R$)'!H96 -> 0 | E28: Abril | F28: IPCA + ANEEL | G28: =D28*(1+#REF!) -> #REF! | H28: 0 | I28: 4305.57 | J28: 4523.8 | K28: =I19 -> 4662.58 | L28: =J19 -> 437.03 | M28: =K19 -> 3506.06 | N28: =L19 -> 1452.88 | O28: =M19 -> 1461.62 | P28: =N19 -> 0 | Q28: =#REF! -> #REF! | R28: =O19 -> 0 | S28: =P19 -> 0 | U28: =SUM(H28:S28) -> #REF!
C29: Rateio Guanambi | H29: 0 | I29: 3413.23 | J29: 3413.23 | K29: =I20 -> 3413.2255 | L29: =J20 -> 3413.2255 | M29: =K20 -> 0 | N29: =L20 -> 6992.6463 | O29: =M20 -> 3579.4208 | P29: =N20 -> 3579.4208 | Q29: =#REF! -> #REF! | R29: =O20 -> 0 | S29: =P20 -> 0 | U29: =SUM(H29:S29) -> #REF!
B30: TOTAL GERAL | H30: =SUM(H28:H29) -> 0 | I30: =SUM(I28:I29) -> 7718.8 | J30: =SUM(J28:J29) -> 7937.03 | K30: =SUM(K28:K29) -> 8075.8055 | L30: =SUM(L28:L29) -> 3850.2555 | M30: =SUM(M28:M29) -> 3506.06 | N30: =SUM(N28:N29) -> 8445.5263 | O30: =SUM(O28:O29) -> 5041.0408 | ... S30: =SUM(S28:S29) -> 0 | U30: =SUM(H30:S30)*-1 -> #REF!
B32: Diferença | H32: =H30/H12 -> 0 | I32: =I30/I12 -> 1.3653779 | J32: =J30/J12 -> 1.4039806 | K32: =K30/K12 -> 1.3369477 | L32: =L30/L12 -> 0.63740889 | M32: =M30/M12 -> 0.52760033 | N32: =N30/N12 -> 1.5485815 | O32: =O30/O12 -> 0.83704478 | ... S32: =S30/S12 -> 0 | U32: =U30/U12 -> #REF!
H35: Movimentações / Vencimento
H37: Mês Ref. | I37: COELBA
H38: JAN | I38: 46113
H39: FEV | I39: 46146
H40: MAR | I40: 46174
H41: ABR | I41: 46204
H42: MAI | I42: 46235
H43: JUN | I43: 46266
H44: JUL | I44: 46296
H45: AGO | I45: 46327
H46: SET | I46: 46357
H47: OUT | I47: 46388
H48: NOV | I48: 46419
H49: DEZ | I49: 46447

Sheet CCS 01
C3: Cemitério Campo Santo, Entrada 1
B5: Provisionado
C7: Consumo (kWh) | E7: Previsão de Consumo (kWh) | G7: ='[1]Rateio UFV - Faturamento (R$)'!G82 -> -1469.9318 | H7: 6652 | I7: 8445 | J7: 6740 | K7: 6740 | L7: 7520 | M7: 5986 | N7: 5522 | O7: 5677 | P7: 5254 | Q7: 5654 | R7: 7113 | S7: 6764
B9: Despesa | D9: Tarifa Out.25 (R$/kWh) | E9: BASE | F9: REAJUSTE | G9: Tarifa + Reajuste | H9: 46023 | I9: 46054 | J9: 46082 | K9: 46113 | L9: 46143 | M9: 46174 | N9: 46204 | O9: 46235 | P9: 46266 | Q9: 46296 | R9: 46327 | S9: 46357 | U9: Total
C10: Coelba | H10: 7782.84 | I10: 9880.65 | J10: 7885.8 | K10: 7885.8 | L10: 8798.4 | M10: 7003.62 | N10: 6460.74 | O10: 6642.09 | P10: 6147.18 | Q10: 6615.18 | R10: 8322.21 | S10: 7913.88 | U10: =SUM(H10:S10) -> 91338.39
C11: Rateio Guanambi | H11: 4327.6091 | I11: 4290.0846 | J11: 4311.4358 | K11: 4318.4345 | L11: 4258.8879 | M11: 4166.1035 | N11: 4269.2096 | O11: 4337.89 | P11: 4214.2027 | Q11: 4464.506 | R11: 4580.14 | S11: 4457.4 | U11: =SUM(H11:S11) -> 51995.904
B12: TOTAL GERAL | H12: =SUM(H10:H11) -> 12110.449 | I12: =SUM(I10:I11) -> 14170.735 | J12: =SUM(J10:J11) -> 12197.236 | K12: =SUM(K10:K11) -> 12204.234 | L12: =SUM(L10:L11) -> 13057.288 | M12: =SUM(M10:M11) -> 11169.724 | N12: =SUM(N10:N11) -> 10729.95 | O12: =SUM(O10:O11) -> 10979.98 | ... S12: =SUM(S10:S11) -> 12371.28 | U12: =SUM(U10:U11)*-1 -> -143334.29
B14: Realizado
C16: Consumo (kWh) | E16: Previsão de Consumo (kWh) | G16: ='[1]Rateio UFV - Faturamento (R$)'!G89 -> 0 | H16: 254 | I16: 3609 | J16: =2095.13+15714.87 -> 17810 | K16: =4527.39+2310.61 -> 6838 | L16: =2294.73+5184.27 -> 7479 | M16: =1411.53+4702.47 -> 6114
B18: Despesa | D18: Tarifa Out.25 (R$/kWh) | E18: BASE | F18: REAJUSTE | G18: Tarifa + Reajuste | H18: 46023 | I18: 46054 | J18: 46082 | K18: 46113 | L18: 46143 | M18: 46174 | N18: 46204 | O18: 46235 | P18: 46266 | Q18: 46296 | R18: 46327 | S18: 46357 | U18: Total
C19: Coelba | D19: ='[1]Rateio UFV - Faturamento (R$)'!H88 -> 0 | E19: Abril | F19: IPCA + ANEEL | G19: =D19*(1+#REF!) -> #REF! | H19: 134.25 | J19: 132.31 | K19: =3140.98+2897.9 -> 6038.88 | L19: 3327.91 | M19: 2220.28 | U19: =SUM(H19:S19) -> 11853.63
C20: Rateio Guanambi | H20: 4081.8335 | I20: 4081.8335 | J20: 4081.8335 | L20: 8362.4179 | M20: 4280.5844 | N20: 4280.5844 | O20: 0 | P20: 0 | Q20: 0 | R20: 0 | S20: 0 | U20: =SUM(I20:S20) -> 25087.254
B21: TOTAL GERAL | H21: =SUM(H19:H20) -> 4216.0835 | I21: =SUM(I19:I20) -> 4081.8335 | J21: =SUM(J19:J20) -> 4214.1435 | K21: =SUM(K19:K20) -> 6038.88 | L21: =SUM(L19:L20) -> 11690.328 | M21: =SUM(M19:M20) -> 6500.8644 | N21: =SUM(N19:N20) -> 4280.5844 | O21: =SUM(O19:O20) -> 0 | ... S21: =SUM(S19:S20) -> 0 | U21: =SUM(U19:U20)*-1 -> -36940.884
B23: Diferença | H23: =H21/H12 -> 0.34813602 | I23: =I21/I12 -> 0.28804671 | J23: =J21/J12 -> 0.34549988 | K23: =K21/K12 -> 0.49481842 | L23: =L21/L12 -> 0.89531057 | M23: =M21/M12 -> 0.58200764 | N23: =N21/N12 -> 0.39893798 | O23: =O21/O12 -> 0 | ... S23: =S21/S12 -> 0 | U23: =U21/U12 -> 0.25772537

Sheet CCS 02
C3: Cemitério Campo Santo, Entrada 2
C4: Obs.: Unidade já fora do Rateio de Guanambi, porém, possui créditos energéticos na unidade, assim, zerando as faturas financeiramente.
B6: Provisionado
C8: Consumo (kWh) | E8: Previsão de Consumo (kWh) | G8: ='[1]Rateio UFV - Faturamento (R$)'!G82 -> -1469.9318 | H8: 308 | I8: 404 | J8: 344 | K8: 284 | L8: 264 | M8: 244 | N8: 304 | O8: 248 | P8: 348 | Q8: 312 | R8: 376 | S8: 300
B10: Despesa | D10: Tarifa Out.25 (R$/kWh) | E10: BASE | F10: REAJUSTE | G10: Tarifa + Reajuste | H10: 46023 | I10: 46054 | J10: 46082 | K10: 46113 | L10: 46143 | M10: 46174 | N10: 46204 | O10: 46235 | P10: 46266 | Q10: 46296 | R10: 46327 | S10: 46357 | U10: Total
C11: Coelba | H11: 385 | I11: 505 | J11: 430 | K11: 379.3175 | L11: 352.605 | M11: 325.8925 | N11: 406.03 | O11: 331.235 | P11: 464.7975 | Q11: 416.715 | R11: 502.195 | S11: 400.6875 | U11: =SUM(H11:S11) -> 4899.475
C12: Rateio Guanambi | H12: 0 | I12: 0 | J12: 0 | K12: 0 | L12: 0 | M12: 0 | N12: 0 | O12: 0 | P12: 0 | Q12: 0 | R12: 0 | S12: 0 | U12: =SUM(H12:S12) -> 0
B13: TOTAL GERAL | H13: =SUM(H11:H12) -> 385 | I13: =SUM(I11:I12) -> 505 | J13: =SUM(J11:J12) -> 430 | K13: =SUM(K11:K12) -> 379.3175 | L13: =SUM(L11:L12) -> 352.605 | M13: =SUM(M11:M12) -> 325.8925 | N13: =SUM(N11:N12) -> 406.03 | O13: =SUM(O11:O12) -> 331.235 | ... S13: =SUM(S11:S12) -> 400.6875 | U13: =SUM(U11:U12)*-1 -> -4899.475
B15: Realizado
C17: Consumo (kWh) | E17: Previsão de Consumo (kWh) | G17: ='[1]Rateio UFV - Faturamento (R$)'!G89 -> 0 | H17: 256 | I17: 248 | J17: 336 | K17: 100 | L17: 428 | M17: 196
B19: Despesa | D19: Tarifa Out.25 (R$/kWh) | E19: BASE | F19: REAJUSTE | G19: Tarifa + Reajuste | H19: 46023 | I19: 46054 | J19: 46082 | K19: 46113 | L19: 46143 | M19: 46174 | N19: 46204 | O19: 46235 | P19: 46266 | Q19: 46296 | R19: 46327 | S19: 46357 | U19: Total
C20: Coelba | D20: ='[1]Rateio UFV - Faturamento (R$)'!H88 -> 0 | E20: Abril | F20: IPCA + ANEEL | G20: =D20*(1+#REF!) -> #REF! | H20: 0 | I20: 0 | J20: 0 | K20: 0 | L20: 0 | M20: 0 | U20: =SUM(H20:S20) -> 0
C21: Rateio Guanambi | H21: 0 | I21: 0 | J21: 0 | K21: 0 | L21: 0 | M21: 0 | N21: 0 | O21: 0 | P21: 0 | Q21: 0 | R21: 0 | S21: 0 | U21: =SUM(H21:S21) -> 0
B22: TOTAL GERAL | H22: =SUM(H20:H21) -> 0 | I22: =SUM(I20:I21) -> 0 | J22: =SUM(J20:J21) -> 0 | K22: =SUM(K20:K21) -> 0 | L22: =SUM(L20:L21) -> 0 | M22: =SUM(M20:M21) -> 0 | N22: =SUM(N20:N21) -> 0 | O22: =SUM(O20:O21) -> 0 | ... S22: =SUM(S20:S21) -> 0 | U22: =SUM(U20:U21)*-1 -> 0
B24: Diferença | H24: =H22/H13 -> 0 | I24: =I22/I13 -> 0 | J24: =J22/J13 -> 0 | K24: =K22/K13 -> 0 | L24: =L22/L13 -> 0 | M24: =M22/M13 -> 0 | N24: =N22/N13 -> 0 | O24: =O22/O13 -> 0 | ... S24: =S22/S13 -> 0 | U24: =U22/U13 -> 0

Sheet Museu da Misericórdia
C3: Museu da Misericórdia
B5: Provisionado
C7: Consumo (kWh) | E7: Previsão de Consumo (kWh) | G7: ='[1]Rateio UFV - Faturamento (R$)'!G82 -> -1469.9318 | H7: 11012.217 | I7: 12506.56 | J7: 10248 | K7: 14282.44 | L7: 13773.01 | M7: 13263.58 | N7: 4938.49 | O7: 8073.44 | P7: 11012.217 | Q7: 11012.217 | R7: 11012.217 | S7: 11012.217
B9: Despesa | D9: Tarifa Out.25 (R$/kWh) | E9: BASE | F9: REAJUSTE | G9: Tarifa + Reajuste | H9: 46023 | I9: 46054 | J9: 46082 | K9: 46113 | L9: 46143 | M9: 46174 | N9: 46204 | O9: 46235 | P9: 46266 | Q9: 46296 | R9: 46327 | S9: 46357 | U9: Total
C10: Coelba | H10: 11783.072 | I10: 13382.019 | J10: 10965.36 | K10: 15282.211 | L10: 14737.121 | M10: 14192.031 | N10: 5284.1843 | O10: 8638.5808 | P10: 11783.072 | Q10: 11783.072 | R10: 11783.072 | S10: 11783.072 | U10: =SUM(H10:S10) -> 141396.87
C11: Rateio Guanambi | H11: 2093.4642 | I11: 2075.3118 | J11: 2085.6404 | K11: 2089.026 | L11: 2060.2205 | M11: 2015.3364 | N11: 2065.2136 | O11: 2098.4375 | P11: 2038.6042 | Q11: 2159.6875 | R11: 2215.625 | S11: 2156.25 | U11: =SUM(H11:S11) -> 25152.817
B12: TOTAL GERAL | H12: =SUM(H10) -> 11783.072 | I12: =SUM(I10) -> 13382.019 | J12: =SUM(J10) -> 10965.36 | K12: =SUM(K10) -> 15282.211 | L12: =SUM(L10) -> 14737.121 | M12: =SUM(M10) -> 14192.031 | N12: =SUM(N10) -> 5284.1843 | O12: =SUM(O10) -> 8638.5808 | ... S12: =SUM(S10) -> 11783.072 | U12: =SUM(U10:U11)*-1 -> -166549.69
B14: Realizado
C16: Consumo (kWh) | E16: Previsão de Consumo (kWh) | G16: ='[1]Rateio UFV - Faturamento (R$)'!G89 -> 0 | H16: =10933.84+705.28+5676.84 -> 17315.96 | I16: 9329.44 | J16: =15336.09+846.32+4925.96 -> 21108.37 | K16: =10480.87+5466.51+606.47 -> 16553.85 | L16: =9956.15+499.87+5038.68 -> 15494.7
B18: Despesa | D18: Tarifa Out.25 (R$/kWh) | E18: BASE | F18: REAJUSTE | G18: Tarifa + Reajuste | H18: 46023 | I18: 46054 | J18: 46082 | K18: 46113 | L18: 46143 | M18: 46174 | N18: 46204 | O18: 46235 | P18: 46266 | Q18: 46296 | R18: 46327 | S18: 46357 | U18: Total
C19: Coelba | D19: ='[1]Rateio UFV - Faturamento (R$)'!H88 -> 0 | E19: Abril | F19: IPCA + ANEEL | G19: =D19*(1+#REF!) -> #REF! | H19: 13465.94 | I19: 18184.06 | J19: 5853 | K19: 20422.33 | L19: 12778.11 | M19: 16497.51 | U19: =SUM(I19:S19) -> 73735.01
C20: Rateio Guanambi | H20: 4373.6569 | I20: 4373.6569 | J20: 4373.6569 | L20: 8960.274 | M20: 4586.6171 | U20: =SUM(I20:S20) -> 22294.205
B21: TOTAL GERAL | H21: =SUM(H19:H20) -> 17839.597 | I21: =SUM(I19:I20) -> 22557.717 | J21: =SUM(J19:J20) -> 10226.657 | K21: =SUM(K19:K20) -> 20422.33 | L21: =SUM(L19:L20) -> 21738.384 | M21: =SUM(M19:M20) -> 21084.127 | N21: =SUM(N19:N20) -> 0 | O21: =SUM(O19:O20) -> 0 | ... S21: =SUM(S19:S20) -> 0 | U21: =SUM(U19:U20)*-1 -> -96029.215
B23: Diferença | H23: =H21/H12 -> 1.5140022 | I23: =I21/I12 -> 1.6856736 | J23: =J21/J12 -> 0.93263303 | K23: =K21/K12 -> 1.3363466 | L23: =L21/L12 -> 1.4750767 | M23: =M21/M12 -> 1.4856315 | N23: =N21/N12 -> 0 | O23: =O21/O12 -> 0 | ... S23: =S21/S12 -> 0 | U23: =U21/U12 -> 0.57657998

Sheet Cuidado Continuo
C3: Cuidado Contínuo
C4: Obs.: Unidade já fora do Rateio de Guanambi, porém, possui créditos energéticos na unidade, assim, zerando as faturas financeiramente.
B6: Provisionado
C8: Consumo (kWh) | E8: Previsão de Consumo (kWh) | G8: ='[1]Rateio UFV - Faturamento (R$)'!G82 -> -1469.9318 | H8: 6265 | I8: 8786 | J8: 7420 | K8: 8020 | L8: 7256 | M8: 5927 | N8: 4902 | O8: 4792 | P8: 4797 | Q8: 5337 | R8: 6190 | S8: 5905
B10: Despesa | D10: Tarifa Out.25 (R$/kWh) | E10: BASE | F10: REAJUSTE | G10: Tarifa + Reajuste | H10: 46023 | I10: 46054 | J10: 46082 | K10: 46113 | L10: 46143 | M10: 46174 | N10: 46204 | O10: 46235 | P10: 46266 | Q10: 46296 | R10: 46327 | S10: 46357 | U10: Total
C11: Coelba | H11: 8269.8 | I11: 11597.52 | J11: 9794.4 | K11: 10586.4 | L11: 9577.92 | M11: 7823.64 | N11: 6470.64 | O11: 6325.44 | P11: 6332.04 | Q11: 7044.84 | R11: 8170.8 | S11: 7794.6 | U11: =SUM(H11:S11) -> 99788.04
C12: Rateio Guanambi | H12: 3681.1474 | I12: 3649.2283 | J12: 3667.3901 | K12: 3673.3432 | L12: 3622.6918 | M12: 3543.7676 | N12: 3631.4716 | O12: 3689.8925 | P12: 3584.6817 | Q12: 3797.5945 | R12: 3895.955 | S12: 3791.55 | U12: =SUM(H12:S12) -> 44228.714
B13: TOTAL GERAL | H13: =SUM(H11:H12) -> 11950.947 | I13: =SUM(I11:I12) -> 15246.748 | J13: =SUM(J11:J12) -> 13461.79 | K13: =SUM(K11:K12) -> 14259.743 | L13: =SUM(L11:L12) -> 13200.612 | M13: =SUM(M11:M12) -> 11367.408 | N13: =SUM(N11:N12) -> 10102.112 | O13: =SUM(O11:O12) -> 10015.333 | ... S13: =SUM(S11:S12) -> 11586.15 | U13: =SUM(U11:U12)*-1 -> -144016.75
B15: Realizado
C17: Consumo (kWh) | E17: Previsão de Consumo (kWh) | G17: ='[1]Rateio UFV - Faturamento (R$)'!G89 -> 0 | H17: 6001 | I17: 6240 | J17: 6957 | K17: 6689 | L17: 5964 | M17: 5369
B19: Despesa | D19: Tarifa Out.25 (R$/kWh) | E19: BASE | F19: REAJUSTE | G19: Tarifa + Reajuste | H19: 46023 | I19: 46054 | J19: 46082 | K19: 46113 | L19: 46143 | M19: 46174 | N19: 46204 | O19: 46235 | P19: 46266 | Q19: 46296 | R19: 46327 | S19: 46357 | U19: Total
C20: Coelba | D20: ='[1]Rateio UFV - Faturamento (R$)'!H88 -> 0 | E20: Abril | F20: IPCA + ANEEL | G20: =D20*(1+#REF!) -> #REF! | H20: 127.79 | I20: 125.64 | J20: 125.16 | K20: 126.05 | L20: 540.72 | M20: 135.17 | U20: =SUM(H20:S20) -> 1180.53
C21: Rateio Guanambi | H21: 0 | I21: 0 | J21: 0 | K21: 0 | L21: 0 | M21: 0 | N21: 0 | O21: 0 | P21: 0 | Q21: 0 | R21: 0 | S21: 0 | U21: =SUM(H21:S21) -> 0
B22: TOTAL GERAL | H22: =SUM(H20:H21) -> 127.79 | I22: =SUM(I20:I21) -> 125.64 | J22: =SUM(J20:J21) -> 125.16 | K22: =SUM(K20:K21) -> 126.05 | L22: =SUM(L20:L21) -> 540.72 | M22: =SUM(M20:M21) -> 135.17 | N22: =SUM(N20:N21) -> 0 | O22: =SUM(O20:O21) -> 0 | ... S22: =SUM(S20:S21) -> 0 | U22: =SUM(U20:U21)*-1 -> -1180.53
B24: Diferença | H24: =H22/H13 -> 0.010692876 | I24: =I22/I13 -> 0.0082404456 | J24: =J22/J13 -> 0.0092974262 | K24: =K22/K13 -> 0.0088395701 | L24: =L22/L13 -> 0.040961738 | M24: =M22/M13 -> 0.011891014 | N24: =N22/N13 -> 0 | O24: =O22/O13 -> 0 | ... S24: =S22/S13 -> 0 | U24: =U22/U13 -> 0.0081971713

Sheet Posto de Coleta
C3: Posto de Coleta
C4: Obs.: Unidade já fora do Rateio de Guanambi, porém, possui créditos energéticos na unidade, assim, zerando as faturas financeiramente.
B6: Provisionado
C8: Consumo (kWh) | E8: Previsão de Consumo (kWh) | G8: ='[1]Rateio UFV - Faturamento (R$)'!G82 -> -1469.9318 | H8: 3053 | I8: 4267 | J8: 4161 | K8: 4347 | L8: 3732 | M8: 3116 | N8: 2525 | O8: 2413 | P8: 2641 | Q8: 2979 | R8: 3437 | S8: 3268
B10: Despesa | D10: Tarifa Out.25 (R$/kWh) | E10: BASE | F10: REAJUSTE | G10: Tarifa + Reajuste | H10: 46023 | I10: 46054 | J10: 46082 | K10: 46113 | L10: 46143 | M10: 46174 | N10: 46204 | O10: 46235 | P10: 46266 | Q10: 46296 | R10: 46327 | S10: 46357 | U10: Total
C11: Coelba | H11: 3419.36 | I11: 4779.04 | J11: 4660.32 | K11: 4868.64 | L11: 4179.84 | M11: 3489.92 | N11: 2828 | O11: 2702.56 | P11: 2957.92 | Q11: 3336.48 | R11: 3849.44 | S11: 3660.16 | U11: =SUM(H11:S11) -> 44731.68
C12: Rateio Guanambi | H12: 2341.3303 | I12: 2321.0288 | J12: 2332.5802 | K12: 2336.3666 | L12: 2304.1506 | M12: 2253.9523 | N12: 2309.7349 | O12: 2346.8925 | P12: 2279.975 | Q12: 2415.3945 | R12: 2477.955 | S12: 2411.55 | U12: =SUM(H12:S12) -> 28130.911
B13: TOTAL GERAL | H13: =SUM(H11:H12) -> 5760.6903 | I13: =SUM(I11:I12) -> 7100.0688 | J13: =SUM(J11:J12) -> 6992.9002 | K13: =SUM(K11:K12) -> 7205.0066 | L13: =SUM(L11:L12) -> 6483.9906 | M13: =SUM(M11:M12) -> 5743.8723 | N13: =SUM(N11:N12) -> 5137.7349 | O13: =SUM(O11:O12) -> 5049.4525 | ... S13: =SUM(S11:S12) -> 6071.71 | U13: =SUM(U11:U12)*-1 -> -72862.591
B15: Realizado
C17: Consumo (kWh) | E17: Previsão de Consumo (kWh) | G17: ='[1]Rateio UFV - Faturamento (R$)'!G89 -> 0 | H17: 2963 | I17: 3589 | J17: 3739 | K17: =3183.05+638.95 -> 3822 | L17: 3368
B19: Despesa | D19: Tarifa Out.25 (R$/kWh) | E19: BASE | F19: REAJUSTE | G19: Tarifa + Reajuste | H19: 46023 | I19: 46054 | J19: 46082 | K19: 46113 | L19: 46143 | M19: 46174 | N19: 46204 | O19: 46235 | P19: 46266 | Q19: 46296 | R19: 46327 | S19: 46357 | U19: Total
C20: Coelba | D20: ='[1]Rateio UFV - Faturamento (R$)'!H88 -> 0 | E20: Abril | F20: IPCA + ANEEL | G20: =D20*(1+#REF!) -> #REF! | H20: 135.1 | I20: 132.81 | J20: 132.31 | K20: 4134.38 | L20: 4545.38 | U20: =SUM(H20:S20) -> 9079.98
C21: Rateio Guanambi | H21: 0 | I21: 0 | J21: 0 | K21: 0 | L21: 0 | M21: 0 | N21: 0 | O21: 0 | P21: 0 | Q21: 0 | R21: 0 | S21: 0 | U21: =SUM(H21:S21) -> 0
B22: TOTAL GERAL | H22: =SUM(H20:H21) -> 135.1 | I22: =SUM(I20:I21) -> 132.81 | J22: =SUM(J20:J21) -> 132.31 | K22: =SUM(K20:K21) -> 4134.38 | L22: =SUM(L20:L21) -> 4545.38 | M22: =SUM(M20:M21) -> 0 | N22: =SUM(N20:N21) -> 0 | O22: =SUM(O20:O21) -> 0 | ... S22: =SUM(S20:S21) -> 0 | U22: =SUM(U20:U21)*-1 -> -9079.98
B24: Diferença | H24: =H22/H13 -> 0.02345205 | I24: =I22/I13 -> 0.018705453 | J24: =J22/J13 -> 0.018920619 | K24: =K22/K13 -> 0.57382043 | L24: =L22/L13 -> 0.70101582 | M24: =M22/M13 -> 0 | N24: =N22/N13 -> 0 | O24: =O22/O13 -> 0 | ... S24: =S22/S13 -> 0 | U24: =U22/U13 -> 0.12461786

Sheet CAF
C3: CAF
B5: Provisionado
C7: Consumo (kWh) | E7: Previsão de Consumo (kWh) | G7: ='[1]Rateio UFV - Faturamento (R$)'!G82 -> -1469.9318 | H7: 13088.4 | I7: 17082 | J7: 19122 | K7: 23091.6 | L7: 23463.6 | M7: 18952.8 | N7: 14484 | O7: 13395.6 | P7: 13906.8 | Q7: 12304 | R7: 15400 | S7: 13268
B9: Despesa | D9: Tarifa Out.25 (R$/kWh) | E9: BASE | F9: REAJUSTE | G9: Tarifa + Reajuste | H9: 46023 | I9: 46054 | J9: 46082 | K9: 46113 | L9: 46143 | M9: 46174 | N9: 46204 | O9: 46235 | P9: 46266 | Q9: 46296 | R9: 46327 | S9: 46357 | U9: Total
C10: Coelba | H10: 15706.08 | I10: 20498.4 | J10: 22946.4 | K10: 27709.92 | L10: 28156.32 | M10: 22743.36 | N10: 17380.8 | O10: 16074.72 | P10: 16688.16 | Q10: 14764.8 | R10: 18480 | S10: 15921.6 | U10: =SUM(H10:S10) -> 237070.56
C11: Rateio Guanambi | H11: 11234.366 | I11: 11136.953 | J11: 11192.381 | K11: 11210.549 | L11: 11055.967 | M11: 10815.102 | N11: 11082.762 | O11: 11261.055 | P11: 10939.966 | Q11: 11589.747 | R11: 11889.93 | S11: 11571.3 | U11: =SUM(H11:S11) -> 134980.08
B12: TOTAL GERAL | H12: =SUM(H10:H11) -> 26940.446 | I12: =SUM(I10:I11) -> 31635.353 | J12: =SUM(J10:J11) -> 34138.781 | K12: =SUM(K10:K11) -> 38920.469 | L12: =SUM(L10:L11) -> 39212.287 | M12: =SUM(M10:M11) -> 33558.462 | N12: =SUM(N10:N11) -> 28463.562 | O12: =SUM(O10:O11) -> 27335.775 | ... S12: =SUM(S10:S11) -> 27492.9 | U12: =SUM(U10:U11)*-1 -> -372050.64
B14: Realizado
C16: Consumo (kWh) | E16: Previsão de Consumo (kWh) | G16: ='[1]Rateio UFV - Faturamento (R$)'!G89 -> 0 | H16: =2919.71+17848.69 -> 20768.4 | I16: 19490.4 | J16: 16702 | K16: =12497.01+5378.19 -> 17875.2 | L16: =2971.38+13397.82 -> 16369.2 | M16: =1091.47+15222.53 -> 16314
B18: Despesa | D18: Tarifa Out.25 (R$/kWh) | E18: BASE | F18: REAJUSTE | G18: Tarifa + Reajuste | H18: 46023 | I18: 46054 | J18: 46082 | K18: 46113 | L18: 46143 | M18: 46174 | N18: 46204 | O18: 46235 | P18: 46266 | Q18: 46296 | R18: 46327 | S18: 46357 | U18: Total
C19: Coelba | D19: ='[1]Rateio UFV - Faturamento (R$)'!H88 -> 0 | E19: Abril | F19: IPCA + ANEEL | G19: =D19*(1+#REF!) -> #REF! | H19: 0 | I19: 0 | J19: 0 | K19: 4574.18 | L19: 4049.16 | M19: 1831.37 | U19: =SUM(H19:S19) -> 10454.71
C20: Rateio Guanambi | H20: 11927.819 | I20: 11927.819 | J20: 11927.819 | L20: 25017.207 | M20: 12508.604 | U20: =SUM(H20:S20) -> 73309.269
B21: TOTAL GERAL | H21: =SUM(H19:H20) -> 11927.819 | I21: =SUM(I19:I20) -> 11927.819 | J21: =SUM(J19:J20) -> 11927.819 | K21: =SUM(K19:K20) -> 4574.18 | L21: =SUM(L19:L20) -> 29066.367 | M21: =SUM(M19:M20) -> 14339.974 | N21: =SUM(N19:N20) -> 0 | O21: =SUM(O19:O20) -> 0 | ... S21: =SUM(S19:S20) -> 0 | U21: =SUM(U19:U20)*-1 -> -83763.979
B23: Diferença | H23: =H21/H12 -> 0.44274766 | I23: =I21/I12 -> 0.37704082 | J23: =J21/J12 -> 0.34939208 | K23: =K21/K12 -> 0.11752633 | L23: =L21/L12 -> 0.74125661 | M23: =M21/M12 -> 0.4273132 | N23: =N21/N12 -> 0 | O23: =O21/O12 -> 0 | ... S23: =S21/S12 -> 0 | U23: =U21/U12 -> 0.22514134

Sheet CAL
C3: Clínica Álvaro Lemos
B5: Provisionado
C7: Consumo (kWh) | E7: Previsão de Consumo (kWh) | G7: ='[1]Rateio UFV - Faturamento (R$)'!G82 -> -1469.9318 | H7: 4283 | I7: 6069 | J7: 4918 | K7: 5311 | L7: 4550 | M7: 3798 | N7: 3598 | O7: 4259 | P7: 3882 | Q7: 4243 | R7: 5402 | S7: 5402
B9: Despesa | D9: Tarifa Out.25 (R$/kWh) | E9: BASE | F9: REAJUSTE | G9: Tarifa + Reajuste | H9: 46023 | I9: 46054 | J9: 46082 | K9: 46113 | L9: 46143 | M9: 46174 | N9: 46204 | O9: 46235 | P9: 46266 | Q9: 46296 | R9: 46327 | S9: 46357 | U9: Total
C10: Coelba | H10: 5396.58 | I10: 7646.94 | J10: 6196.68 | K10: 6691.86 | L10: 5733 | M10: 4785.48 | N10: 4533.48 | O10: 5366.34 | P10: 4891.32 | Q10: 5346.18 | R10: 6806.52 | S10: 6806.52 | U10: =SUM(H10:S10) -> 70200.9
C11: Rateio Guanambi | H11: 3590.7097 | I11: 3559.5749 | J11: 3577.2904 | K11: 3583.0973 | L11: 3533.6902 | M11: 3456.7051 | N11: 3542.2544 | O11: 3599.24 | P11: 3496.614 | Q11: 3704.296 | R11: 3800.24 | S11: 3698.4 | U11: =SUM(H11:S11) -> 43142.112
B12: TOTAL GERAL | H12: =SUM(H10:H11) -> 8987.2897 | I12: =SUM(I10:I11) -> 11206.515 | J12: =SUM(J10:J11) -> 9773.9704 | K12: =SUM(K10:K11) -> 10274.957 | L12: =SUM(L10:L11) -> 9266.6902 | M12: =SUM(M10:M11) -> 8242.1851 | N12: =SUM(N10:N11) -> 8075.7344 | O12: =SUM(O10:O11) -> 8965.58 | ... S12: =SUM(S10:S11) -> 10504.92 | U12: =SUM(U10:U11)*-1 -> -113343.01
B14: Realizado
C16: Consumo (kWh) | E16: Previsão de Consumo (kWh) | G16: ='[1]Rateio UFV - Faturamento (R$)'!G89 -> 0 | H16: =4846+100 -> 4946 | I16: 5640 | J16: 5825 | K16: 141 | L16: 10975 | M16: 3767
B18: Despesa | D18: Tarifa Out.25 (R$/kWh) | E18: BASE | F18: REAJUSTE | G18: Tarifa + Reajuste | H18: 46023 | I18: 46054 | J18: 46082 | K18: 46113 | L18: 46143 | M18: 46174 | N18: 46204 | O18: 46235 | P18: 46266 | Q18: 46296 | R18: 46327 | S18: 46357 | U18: Total
C19: Coelba | D19: ='[1]Rateio UFV - Faturamento (R$)'!H88 -> 0 | E19: Abril | F19: IPCA + ANEEL | G19: =D19*(1+#REF!) -> #REF! | H19: 134.74 | I19: 132.81 | J19: 119.67 | K19: 133.25 | L19: 141.14 | M19: 142.91 | U19: =SUM(H19:S19) -> 804.52
C20: Rateio Guanambi | H20: 3180.5056 | I20: 3180.5056 | J20: 3180.5056 | L20: 6670.7387 | M20: 3335.3694 | U20: =SUM(H20:S20) -> 19547.625
B21: TOTAL GERAL | H21: =SUM(H19:H20) -> 3315.2456 | I21: =SUM(I19:I20) -> 3313.3156 | J21: =SUM(J19:J20) -> 3300.1756 | K21: =SUM(K19:K20) -> 133.25 | L21: =SUM(L19:L20) -> 6811.8787 | M21: =SUM(M19:M20) -> 3478.2794 | N21: =SUM(N19:N20) -> 0 | O21: =SUM(O19:O20) -> 0 | ... S21: =SUM(S19:S20) -> 0 | U21: =SUM(U19:U20)*-1 -> -20352.145
B23: Diferença | H23: =H21/H12 -> 0.36888157 | I23: =I21/I12 -> 0.29565977 | J23: =J21/J12 -> 0.33764943 | K23: =K21/K12 -> 0.012968424 | L23: =L21/L12 -> 0.73509295 | M23: =M21/M12 -> 0.42200937 | N23: =N21/N12 -> 0 | O23: =O21/O12 -> 0 | ... S23: =S21/S12 -> 0 | U23: =U21/U12 -> 0.17956241

Sheet Casa Azul
C3: Casa Azul
B5: Provisionado
C7: Consumo (kWh) | E7: Previsão de Consumo (kWh) | G7: ='[1]Rateio UFV - Faturamento (R$)'!G82 -> -1469.9318 | H7: 5697 | I7: 7154 | J7: 6672 | K7: 6288 | L7: 5429 | M7: 5337 | N7: 3917 | O7: 4144 | P7: 4481 | Q7: 4812 | R7: 6482 | S7: 5864
B9: Despesa | D9: Tarifa Out.25 (R$/kWh) | E9: BASE | F9: REAJUSTE | G9: Tarifa + Reajuste | H9: 46023 | I9: 46054 | J9: 46082 | K9: 46113 | L9: 46143 | M9: 46174 | N9: 46204 | O9: 46235 | P9: 46266 | Q9: 46296 | R9: 46327 | S9: 46357 | U9: Total
C10: Coelba | H10: 7121.25 | I10: 8942.5 | J10: 8340 | K10: 7860 | L10: 6786.25 | M10: 6671.25 | N10: 4896.25 | O10: 5180 | P10: 5601.25 | Q10: 6015 | R10: 8102.5 | S10: 7330 | U10: =SUM(H10:S10) -> 82846.25
C11: Rateio Guanambi | H11: 3915.6154 | I11: 3881.6633 | J11: 3900.9818 | K11: 3907.3141 | L11: 3853.4365 | M11: 3769.4853 | N11: 3862.7755 | O11: 3924.9175 | P11: 3813.0054 | Q11: 4039.4795 | R11: 4144.105 | S11: 4033.05 | U11: =SUM(H11:S11) -> 47045.829
B12: TOTAL GERAL | H12: =SUM(H10:H11) -> 11036.865 | I12: =SUM(I10:I11) -> 12824.163 | J12: =SUM(J10:J11) -> 12240.982 | K12: =SUM(K10:K11) -> 11767.314 | L12: =SUM(L10:L11) -> 10639.686 | M12: =SUM(M10:M11) -> 10440.735 | N12: =SUM(N10:N11) -> 8759.0255 | O12: =SUM(O10:O11) -> 9104.9175 | ... S12: =SUM(S10:S11) -> 11363.05 | U12: =SUM(U10:U11)*-1 -> -129892.08
B14: Realizado
C16: Consumo (kWh) | E16: Previsão de Consumo (kWh) | G16: ='[1]Rateio UFV - Faturamento (R$)'!G89 -> 0 | H16: 5773 | I16: 5716 | J16: 5574 | K16: 6061 | L16: 4468 | M16: =4139.09+353.91 -> 4493
B18: Despesa | D18: Tarifa Out.25 (R$/kWh) | E18: BASE | F18: REAJUSTE | G18: Tarifa + Reajuste | H18: 46023 | I18: 46054 | J18: 46082 | K18: 46113 | L18: 46143 | M18: 46174 | N18: 46204 | O18: 46235 | P18: 46266 | Q18: 46296 | R18: 46327 | S18: 46357 | U18: Total
C19: Coelba | D19: ='[1]Rateio UFV - Faturamento (R$)'!H88 -> 0 | E19: Abril | F19: IPCA + ANEEL | G19: =D19*(1+#REF!) -> #REF! | H19: 135.41 | I19: 132.31 | J19: 132.31 | K19: 133.25 | L19: 138.56 | M19: 537.82 | U19: =SUM(H19:S19) -> 1209.66
C20: Rateio Guanambi | H20: 3232.2211 | I20: 3232.2211 | J20: 3232.2211 | L20: 6779.206 | M20: 3389.603 | U20: =SUM(H20:S20) -> 19865.472
